Workbook

Sheet VaR Calculator
B2: 📊 VALUE AT RISK (VaR) CALCULATOR
B3: Measure the maximum expected portfolio loss at a given confidence level
B5: USER INPUTS | G5: STATISTICAL SUMMARY
B6: Portfolio Value ($) | C6: 1000000 | D6: ← Enter your portfolio value | G6: Number of Observations | H6: =COUNT(C12:C36,E12:E36) -> 50
B7: Confidence Level | C7: 0.95 | D7: ← Common: 90%, 95%, 99% | G7: Mean Daily Return | H7: =AVERAGE(C12:C36,E12:E36) -> -0.00033
B8: Time Horizon (days) | C8: 1 | D8: ← 1=daily, 5=weekly, 21=monthly | G8: Std Deviation (Daily) | H8: =STDEV(C12:C36,E12:E36) -> 0.01015766
G9: Min Daily Return | H9: =MIN(C12:C36,E12:E36) -> -0.0241
B10: HISTORICAL DAILY RETURNS | G10: Max Daily Return | H10: =MAX(C12:C36,E12:E36) -> 0.0149
B11: Day | C11: Daily Return | D11: Day | E11: Daily Return | G11: Skewness | H11: =SKEW(C12:C36,E12:E36) -> -0.57784304
B12: 1 | C12: 0.0082 | D12: 26 | E12: 0.0011 | G12: Kurtosis | H12: =KURT(C12:C36,E12:E36) -> -0.57171449
B13: 2 | C13: -0.0134 | D13: 27 | E13: -0.0178
B14: 3 | C14: 0.0051 | D14: 28 | E14: 0.0092 | G14: SORTED RETURNS (Worst → Best)
B15: 4 | C15: -0.0023 | D15: 29 | E15: -0.0025 | G15: Rank | H15: Sorted Return | I15: Percentile
B16: 5 | C16: 0.0115 | D16: 30 | E16: 0.0137 | G16: 1 | H16: =SMALL((C$12:C$36,E$12:E$36),G16) -> -0.0241 | I16: =G16/H$6 -> 0.02
B17: 6 | C17: -0.0198 | D17: 31 | E17: -0.0054 | G17: 2 | H17: =SMALL((C$12:C$36,E$12:E$36),G17) -> -0.0201 | I17: =G17/H$6 -> 0.04
B18: 7 | C18: 0.0067 | D18: 32 | E18: 0.0066 | G18: 3 | H18: =SMALL((C$12:C$36,E$12:E$36),G18) -> -0.0198 | I18: =G18/H$6 -> 0.06
B19: 8 | C19: 0.0029 | D19: 33 | E19: -0.0113 | G19: 4 | H19: =SMALL((C$12:C$36,E$12:E$36),G19) -> -0.0178 | I19: =G19/H$6 -> 0.08
B20: 9 | C20: -0.0071 | D20: 34 | E20: 0.0087 | G20: 5 | H20: =SMALL((C$12:C$36,E$12:E$36),G20) -> -0.0168 | I20: =G20/H$6 -> 0.1
B21: 10 | C21: 0.0143 | D21: 35 | E21: -0.0008 | G21: 6 | H21: =SMALL((C$12:C$36,E$12:E$36),G21) -> -0.0156 | I21: =G21/H$6 -> 0.12
B22: 11 | C22: -0.0045 | D22: 36 | E22: 0.0149 | G22: 7 | H22: =SMALL((C$12:C$36,E$12:E$36),G22) -> -0.0147 | I22: =G22/H$6 -> 0.14
B23: 12 | C23: 0.0098 | D23: 37 | E23: -0.0062 | G23: 8 | H23: =SMALL((C$12:C$36,E$12:E$36),G23) -> -0.0134 | I23: =G23/H$6 -> 0.16
B24: 13 | C24: -0.0156 | D24: 38 | E24: 0.0038 | G24: 9 | H24: =SMALL((C$12:C$36,E$12:E$36),G24) -> -0.0113 | I24: =G24/H$6 -> 0.18
B25: 14 | C25: 0.0034 | D25: 39 | E25: -0.0201 | G25: 10 | H25: =SMALL((C$12:C$36,E$12:E$36),G25) -> -0.0096 | I25: =G25/H$6 -> 0.2
B26: 15 | C26: -0.0012 | D26: 40 | E26: 0.0074
B27: 16 | C27: 0.0076 | D27: 41 | E27: 0.0023 | G27: VaR RESULTS
B28: 17 | C28: -0.0089 | D28: 42 | E28: -0.0096
B29: 18 | C29: 0.0121 | D29: 43 | E29: 0.0055 | G29: 📊 METHOD 1: HISTORICAL VaR
B30: 19 | C30: -0.0033 | D30: 44 | E30: -0.0147 | G30: Approach: | H30: Sort actual returns, find the percentile cutoff
B31: 20 | C31: 0.0058 | D31: 45 | E31: 0.0112 | G31: VaR Percentile Return | H31: =SMALL((C$12:C$36,E$12:E$36),MAX(1,ROUND((1-C7)*H6,0))) -> -0.0198 | I31: daily return
B32: 21 | C32: -0.0241 | D32: 46 | E32: -0.0031 | G32: Adj. for Time Horizon | H32: =H31*SQRT(C8) -> -0.0198 | I32: scaled return
B33: 22 | C33: 0.0019 | D33: 47 | E33: 0.0084 | G33: ⚠️ Historical VaR ($) | H33: =ABS(H32)*C6 -> 19800 | I33: max expected loss
B34: 23 | C34: 0.0103 | D34: 48 | E34: -0.0043
B35: 24 | C35: -0.0067 | D35: 49 | E35: 0.0061 | G35: 📈 METHOD 2: PARAMETRIC VaR
B36: 25 | C36: 0.0045 | D36: 50 | E36: -0.0168 | G36: Approach: | H36: Assume normal distribution; use mean & std dev
B37: ✏️ Replace the blue values above with your own portfolio's daily returns | G37: Z-Score at Confidence | H37: =_xlfn.NORM.S.INV(1-C7) -> -1.6448536 | I37: left-tail z
G38: VaR Daily Return | H38: =H7+H37*H8 -> -0.017037864 | I38: = μ + zσ
B39: QUICK REFERENCE GUIDE | G39: Adj. for Time Horizon | H39: =H38*SQRT(C8) -> -0.017037864 | I39: scaled return
B40: 🔵 Blue text | C40: = Editable inputs (change these!) | G40: ⚠️ Parametric VaR ($) | H40: =ABS(H39)*C6 -> 17037.864 | I40: max expected loss
B41: ⚫ Black text | C41: = Calculated formulas (auto-updates)
B42: 🔴 Red text | C42: = VaR loss amounts | G42: 🔄 METHOD COMPARISON
...

Sheet Distribution Chart
A1: Bin Label | B1: Frequency | C1: VaR Zone | D1: Safe Zone
A2: < -2.0% | B2: =COUNTIF('VaR Calculator'!C$12:C$36,"<"&-0.02)+COUNTIF('VaR Calculator'!E$12:E$36,"<"&-0.02) -> 2 | C2: =IF(-1<'VaR Calculator'!H31,B2,0) -> 2 | D2: =IF(-1<'VaR Calculator'!H31,0,B2) -> 0
A3: -2.0 to -1.5% | B3: =COUNTIFS('VaR Calculator'!C$12:C$36,">="&-0.02,'VaR Calculator'!C$12:C$36,"<"&-0.015)+COUNTIFS('VaR Calculator'!E$12:E$36,">="&-0.02,'VaR Calculator'!E$12:E$36,"<"&-0.015) -> 4 | C3: =IF(-0.02<'VaR Calculator'!H31,B3,0) -> 4 | D3: =IF(-0.02<'VaR Calculator'!H31,0,B3) -> 0
A4: -1.5 to -1.0% | B4: =COUNTIFS('VaR Calculator'!C$12:C$36,">="&-0.015,'VaR Calculator'!C$12:C$36,"<"&-0.01)+COUNTIFS('VaR Calculator'!E$12:E$36,">="&-0.015,'VaR Calculator'!E$12:E$36,"<"&-0.01) -> 3 | C4: =IF(-0.015<'VaR Calculator'!H31,B4,0) -> 0 | D4: =IF(-0.015<'VaR Calculator'!H31,0,B4) -> 3
A5: -1.0 to -0.5% | B5: =COUNTIFS('VaR Calculator'!C$12:C$36,">="&-0.01,'VaR Calculator'!C$12:C$36,"<"&-0.005)+COUNTIFS('VaR Calculator'!E$12:E$36,">="&-0.01,'VaR Calculator'!E$12:E$36,"<"&-0.005) -> 6 | C5: =IF(-0.01<'VaR Calculator'!H31,B5,0) -> 0 | D5: =IF(-0.01<'VaR Calculator'!H31,0,B5) -> 6
A6: -0.5 to 0% | B6: =COUNTIFS('VaR Calculator'!C$12:C$36,">="&-0.005,'VaR Calculator'!C$12:C$36,"<"&0)+COUNTIFS('VaR Calculator'!E$12:E$36,">="&-0.005,'VaR Calculator'!E$12:E$36,"<"&0) -> 8 | C6: =IF(-0.005<'VaR Calculator'!H31,B6,0) -> 0 | D6: =IF(-0.005<'VaR Calculator'!H31,0,B6) -> 8
A7: 0 to 0.5% | B7: =COUNTIFS('VaR Calculator'!C$12:C$36,">="&0,'VaR Calculator'!C$12:C$36,"<"&0.005)+COUNTIFS('VaR Calculator'!E$12:E$36,">="&0,'VaR Calculator'!E$12:E$36,"<"&0.005) -> 7 | C7: =IF(0<'VaR Calculator'!H31,B7,0) -> 0 | D7: =IF(0<'VaR Calculator'!H31,0,B7) -> 7
A8: 0.5 to 1.0% | B8: =COUNTIFS('VaR Calculator'!C$12:C$36,">="&0.005,'VaR Calculator'!C$12:C$36,"<"&0.01)+COUNTIFS('VaR Calculator'!E$12:E$36,">="&0.005,'VaR Calculator'!E$12:E$36,"<"&0.01) -> 13 | C8: =IF(0.005<'VaR Calculator'!H31,B8,0) -> 0 | D8: =IF(0.005<'VaR Calculator'!H31,0,B8) -> 13
A9: 1.0 to 1.5% | B9: =COUNTIFS('VaR Calculator'!C$12:C$36,">="&0.01,'VaR Calculator'!C$12:C$36,"<"&0.015)+COUNTIFS('VaR Calculator'!E$12:E$36,">="&0.01,'VaR Calculator'!E$12:E$36,"<"&0.015) -> 7 | C9: =IF(0.01<'VaR Calculator'!H31,B9,0) -> 0 | D9: =IF(0.01<'VaR Calculator'!H31,0,B9) -> 7
A10: > 1.5% | B10: =COUNTIF('VaR Calculator'!C$12:C$36,">="&0.015)+COUNTIF('VaR Calculator'!E$12:E$36,">="&0.015) -> 0 | C10: =IF(0.015<'VaR Calculator'!H31,B10,0) -> 0 | D10: =IF(0.015<'VaR Calculator'!H31,0,B10) -> 0
